Workbook
Name IQ_CH: 110000
Name IQ_CQ: 5000
Name IQ_CY: 10000
Name IQ_DAILY: 500000
Name IQ_FH: 100000
Name IQ_FQ: 500
Name IQ_FY: 1000
Name IQ_LTM: 2000
Name IQ_MONTH: 15000
Name IQ_NTM: 6000
Name IQ_WEEK: 50000
Name IQ_YTD: 3000
Name UPDATE: 'Data Sheet'!$E$1

Sheet Intrinsic growth
B3: MAHINDRA AND MAHINDRA LTD PROJECT
B8: Calculation of ROIC | E8: 43921 | F8: 44286 | G8: 44651 | H8: 45016 | I8: 45382 | J8: 45747
B10: Current Asset
B11: ='Raw Data (Source)'!D123 -> Inventories | E11: ='Raw Data (Source)'!K123 -> 11112 | F11: ='Raw Data (Source)'!L123 -> 9615 | G11: ='Raw Data (Source)'!M123 -> 11596 | H11: ='Raw Data (Source)'!N123 -> 16855 | I11: ='Raw Data (Source)'!O123 -> 18590 | J11: ='Raw Data (Source)'!P123 -> 20331
B12: ='Raw Data (Source)'!D124 -> Trade receivables | E12: ='Raw Data (Source)'!K124 -> 6928 | F12: ='Raw Data (Source)'!L124 -> 6008 | G12: ='Raw Data (Source)'!M124 -> 6374 | H12: ='Raw Data (Source)'!N124 -> 7028 | I12: ='Raw Data (Source)'!O124 -> 7459 | J12: ='Raw Data (Source)'!P124 -> 8280
B13: ='Raw Data (Source)'!D126 -> Loans n Advances | E13: ='Raw Data (Source)'!K126 -> 27859 | F13: ='Raw Data (Source)'!L126 -> 29080 | G13: ='Raw Data (Source)'!M126 -> 29242 | H13: ='Raw Data (Source)'!N126 -> 34685 | I13: ='Raw Data (Source)'!O126 -> 39060 | J13: ='Raw Data (Source)'!P126 -> 44645
B14: ='Raw Data (Source)'!D127 -> Other asset items | E14: ='Raw Data (Source)'!K127 -> 56150 | F14: ='Raw Data (Source)'!L127 -> 49383 | G14: ='Raw Data (Source)'!M127 -> 51277 | H14: ='Raw Data (Source)'!N127 -> 68061 | I14: ='Raw Data (Source)'!O127 -> 86222 | J14: ='Raw Data (Source)'!P127 -> 97900
B15: Total Current Assets | E15: =SUM(E11:E14) -> 102049 | F15: =SUM(F11:F14) -> 94086 | G15: =SUM(G11:G14) -> 98489 | H15: =SUM(H11:H14) -> 126629 | I15: =SUM(I11:I14) -> 151331 | J15: =SUM(J11:J14) -> 171156
B17: Current Liabilities
B18: ='Raw Data (Source)'!D101 -> Trade Payables | E18: ='Raw Data (Source)'!K101 -> 14985 | F18: ='Raw Data (Source)'!L101 -> 15506 | G18: ='Raw Data (Source)'!M101 -> 19037 | H18: ='Raw Data (Source)'!N101 -> 23836 | I18: ='Raw Data (Source)'!O101 -> 25666 | J18: ='Raw Data (Source)'!P101 -> 30855
B19: ='Raw Data (Source)'!D102 -> Advance from Customers | E19: ='Raw Data (Source)'!K102 -> 0 | F19: ='Raw Data (Source)'!L102 -> 0 | G19: ='Raw Data (Source)'!M102 -> 0 | H19: ='Raw Data (Source)'!N102 -> 0 | I19: ='Raw Data (Source)'!O102 -> 0 | J19: ='Raw Data (Source)'!P102 -> 0
B20: ='Raw Data (Source)'!D103 -> Other liability items | E20: ='Raw Data (Source)'!K103 -> 20977 | F20: ='Raw Data (Source)'!L103 -> 18185 | G20: ='Raw Data (Source)'!M103 -> 18921 | H20: ='Raw Data (Source)'!N103 -> 21119 | I20: ='Raw Data (Source)'!O103 -> 22900 | J20: ='Raw Data (Source)'!P103 -> 27035
B21: Total Current Liabilities | E21: =SUM(E18:E20) -> 35962 | F21: =SUM(F18:F20) -> 33691 | G21: =SUM(G18:G20) -> 37958 | H21: =SUM(H18:H20) -> 44955 | I21: =SUM(I18:I20) -> 48566 | J21: =SUM(J18:J20) -> 57890
A23: # | B23: Net Working Capital | E23: =E15-E21 -> 66087 | F23: =F15-F21 -> 60395 | G23: =G15-G21 -> 60531 | H23: =H15-H21 -> 81674 | I23: =I15-I21 -> 102765 | J23: =J15-J21 -> 113266
B25: Non Current Asset
B26: ='Raw Data (Source)'!D107 -> Land | E26: ='Raw Data (Source)'!K107 -> 4511 | F26: ='Raw Data (Source)'!L107 -> 1712 | G26: ='Raw Data (Source)'!M107 -> 1931 | H26: ='Raw Data (Source)'!N107 -> 1977 | I26: ='Raw Data (Source)'!O107 -> 2098 | J26: ='Raw Data (Source)'!P107 -> 2115
B27: ='Raw Data (Source)'!D108 -> Building | E27: ='Raw Data (Source)'!K108 -> 11956 | F27: ='Raw Data (Source)'!L108 -> 8482 | G27: ='Raw Data (Source)'!M108 -> 9728 | H27: ='Raw Data (Source)'!N108 -> 10862 | I27: ='Raw Data (Source)'!O108 -> 11496 | J27: ='Raw Data (Source)'!P108 -> 13100
B28: ='Raw Data (Source)'!D109 -> Plant Machinery | E28: ='Raw Data (Source)'!K109 -> 38492 | F28: ='Raw Data (Source)'!L109 -> 22386 | G28: ='Raw Data (Source)'!M109 -> 26484 | H28: ='Raw Data (Source)'!N109 -> 24928 | I28: ='Raw Data (Source)'!O109 -> 27230 | J28: ='Raw Data (Source)'!P109 -> 32547
B29: ='Raw Data (Source)'!D110 -> Equipments | E29: ='Raw Data (Source)'!K110 -> 417 | F29: ='Raw Data (Source)'!L110 -> 418 | G29: ='Raw Data (Source)'!M110 -> 445 | H29: ='Raw Data (Source)'!N110 -> 452 | I29: ='Raw Data (Source)'!O110 -> 481 | J29: ='Raw Data (Source)'!P110 -> 493
B30: ='Raw Data (Source)'!D111 -> Furniture n fittings | E30: ='Raw Data (Source)'!K111 -> 1160 | F30: ='Raw Data (Source)'!L111 -> 805 | G30: ='Raw Data (Source)'!M111 -> 844 | H30: ='Raw Data (Source)'!N111 -> 925 | I30: ='Raw Data (Source)'!O111 -> 1011 | J30: ='Raw Data (Source)'!P111 -> 1118
B31: ='Raw Data (Source)'!D112 -> Vehicles | E31: ='Raw Data (Source)'!K112 -> 1068 | F31: ='Raw Data (Source)'!L112 -> 986 | G31: ='Raw Data (Source)'!M112 -> 1090 | H31: ='Raw Data (Source)'!N112 -> 1238 | I31: ='Raw Data (Source)'!O112 -> 1356 | J31: ='Raw Data (Source)'!P112 -> 1593
B32: ='Raw Data (Source)'!D113 -> Intangible Assets | E32: ='Raw Data (Source)'!K113 -> 9733 | F32: ='Raw Data (Source)'!L113 -> 6932 | G32: ='Raw Data (Source)'!M113 -> 7046 | H32: ='Raw Data (Source)'!N113 -> 10625 | I32: ='Raw Data (Source)'!O113 -> 11589 | J32: ='Raw Data (Source)'!P113 -> 13723
B33: ='Raw Data (Source)'!D114 -> Other fixed assets | E33: ='Raw Data (Source)'!K114 -> 1265 | F33: ='Raw Data (Source)'!L114 -> 937 | G33: ='Raw Data (Source)'!M114 -> 958 | H33: ='Raw Data (Source)'!N114 -> 1084 | I33: ='Raw Data (Source)'!O114 -> 1202 | J33: ='Raw Data (Source)'!P114 -> 1454
B34: Gross Block | E34: =SUM(E26:E33) -> 68602 | F34: =SUM(F26:F33) -> 42658 | G34: =SUM(G26:G33) -> 48526 | H34: =SUM(H26:H33) -> 52091 | I34: =SUM(I26:I33) -> 56463 | J34: =SUM(J26:J33) -> 66143
B35: Accumulated Deprication | E35: =-'Raw Data (Source)'!K116 -> -38913 | F35: =-'Raw Data (Source)'!L116 -> -21278 | G35: =-'Raw Data (Source)'!M116 -> -22508 | H35: =-'Raw Data (Source)'!N116 -> -24950 | I35: =-'Raw Data (Source)'!O116 -> -28333 | J35: =-'Raw Data (Source)'!P116 -> -31506
B36: Net Non Current Asset | E36: =SUM(E34:E35) -> 29689 | F36: =SUM(F34:F35) -> 21380 | G36: =SUM(G34:G35) -> 26018 | H36: =SUM(H34:H35) -> 27141 | I36: =SUM(I34:I35) -> 28130 | J36: =SUM(J34:J35) -> 34637
A38: # | B38: Invested Capital | E38: =SUM(E36,E23) -> 95776 | F38: =SUM(F36,F23) -> 81775 | G38: =SUM(G36,G23) -> 86549 | H38: =SUM(H36,H23) -> 108815 | I38: =SUM(I36,I23) -> 130895 | J38: =SUM(J36,J23) -> 147903
B39: EBIT | E39: ='[1]M&M PROJECT 3 Statement'!C22-'[1]M&M PROJECT 3 Statement'!C28 -> 6791.07 | F39: ='[1]M&M PROJECT 3 Statement'!D22-'[1]M&M PROJECT 3 Statement'!D28 -> 8108.91 | G39: ='[1]M&M PROJECT 3 Statement'!E22-'[1]M&M PROJECT 3 Statement'!E28 -> 11175.35 | H39: ='[1]M&M PROJECT 3 Statement'!F22-'[1]M&M PROJECT 3 Statement'!F28 -> 15928.48 | I39: ='[1]M&M PROJECT 3 Statement'!G22-'[1]M&M PROJECT 3 Statement'!G28 -> 20168.15 | J39: ='[1]M&M PROJECT 3 Statement'!H22-'[1]M&M PROJECT 3 Statement'!H28 -> 24444.54
A41: # | B41: ROIC | E41: =E39/E38 -> 0.070905759 | F41: =F39/F38 -> 0.099161235 | G41: =G39/G38 -> 0.12912165 | H41: =H39/H38 -> 0.14638129 | I41: =I39/I38 -> 0.15407884 | J41: =J39/J38 -> 0.16527413
B43: Calculation of Reinvestment Rate | E43: 43921 | F43: 44286 | G43: 44651 | H43: 45016 | I43: 45382 | J43: 45747
B45: Net Capex | E45: =-SUM('Raw Data (Source)'!K141:K142) -> 6794 | F45: =-SUM('Raw Data (Source)'!L141:L142) -> 4625 | G45: =-SUM('Raw Data (Source)'!M141:M142) -> 5920 | H45: =-SUM('Raw Data (Source)'!N141:N142) -> 6167 | I45: =-SUM('Raw Data (Source)'!O141:O142) -> 9673 | J45: =-SUM('Raw Data (Source)'!P141:P142) -> 9809
B46: Change in working capital | F46: =F23-E23 -> -5692 | G46: =G23-F23 -> 136 | H46: =H23-G23 -> 21143 | I46: =I23-H23 -> 21091 | J46: =J23-I23 -> 10501
B48: EBIT | E48: =E39 -> 6791.07 | F48: =F39 -> 8108.91 | G48: =G39 -> 11175.35 | H48: =H39 -> 15928.48 | I48: =I39 -> 20168.15 | J48: =J39 -> 24444.54
B49: Marginal Tax | E49: 0.25 | F49: 0.25 | G49: 0.25 | H49: 0.25 | I49: 0.25 | J49: 0.25
B50: EBIT(1-T) | E50: =E48*(1-E49) -> 5093.3025 | F50: =F48*(1-F49) -> 6081.6825 | G50: =G48*(1-G49) -> 8381.5125 | H50: =H48*(1-H49) -> 11946.36 | I50: =I48*(1-I49) -> 15126.112 | J50: =J48*(1-J49) -> 18333.405
B52: Reinvestment | F52: =SUM(F45:F46) -> -1067 | G52: =SUM(G45:G46) -> 6056 | H52: =SUM(H45:H46) -> 27310 | I52: =SUM(I45:I46) -> 30764 | J52: =SUM(J45:J46) -> 20310
B54: Reinvestment Rate | F54: =F52/F50 -> -0.17544487 | G54: =G52/G50 -> 0.72254262 | H54: =H52/H50 -> 2.286052 | I54: =I52/I50 -> 2.0338339 | J54: =J52/J50 -> 1.1078139
I56: 4 Years Average | J56: =AVERAGE(F54:J54) -> 1.1949595
I57: 4 Years Median | J57: =MEDIAN(F54:J54) -> 1.1078139
B59: Calculation of Growth Rate | E59: 43921 | F59: 44286 | G59: 44651 | H59: 45016 | I59: 45382 | J59: 45747
...

Sheet PV OF FCF
B2: MAHINDRA AND MAHINDRA LTD PROJECT
B6: Calculation of PV of FCF | D6: =TEXT(DATE(2025,3,31),"mmm-yy")&"A" -> Mar-25A | E6: =TEXT(DATE(2026,3,31),"mmm-yy")&"E" -> Mar-26E | F6: =TEXT(DATE(2027,3,31),"mmm-yy")&"E" -> Mar-27E | G6: =TEXT(DATE(2028,3,31),"mmm-yy")&"E" -> Mar-28E | H6: =TEXT(DATE(2029,3,31),"mmm-yy")&"E" -> Mar-29E | I6: =TEXT(DATE(2030,3,31),"mmm-yy")&"E" -> Mar-30E
B8: EBIT | D8: ='[1]M&M PROJECT 3 Statement'!H22-'[1]M&M PROJECT 3 Statement'!H28 -> 24444.54 | E8: =D8*(1+$D$18) -> 27866.776 | F8: =E8*(1+$D$18) -> 31768.124 | G8: =F8*(1+$D$18) -> 36215.662 | H8: =G8*(1+$D$18) -> 41285.854 | I8: =H8*(1+$D$18) -> 47065.874
B9: Tax Rate | D9: 0.25 | E9: 0.25 | F9: 0.25 | G9: 0.25 | H9: 0.25 | I9: 0.25
B10: EBIT(1-T) | D10: =D8*(1-D9) -> 18333.405 | E10: =E8*(1-E9) -> 20900.082 | F10: =F8*(1-F9) -> 23826.093 | G10: =G8*(1-G9) -> 27161.746 | H10: =H8*(1-H9) -> 30964.391 | I10: =I8*(1-I9) -> 35299.405
B11: Less: Reinvestment Rate | D11: ='Intrinsic growth'!J57 -> 1.1078139 | E11: 1.0382 | F11: 0.9686 | G11: 0.899 | H11: 0.8294 | I11: 0.76
B12: Free Cash Flow to Firm (FCFF) | D12: =D10*(1-D11) -> -1976.595 | E12: =E10*(1-E11) -> -798.38312 | F12: =F10*(1-F11) -> 748.13932 | G12: =G10*(1-G11) -> 2743.3364 | H12: =H10*(1-H11) -> 5282.525 | I12: =I10*(1-I11) -> 8471.8573
B13: Mid Year Convention | E13: 0.5 | F13: =E13+1 -> 1.5 | G13: =F13+1 -> 2.5 | H13: =G13+1 -> 3.5 | I13: =H13+1 -> 4.5
B14: Discounting Factor | E14: =1/(1+$D$20)^E13 -> 0.9469577 | F14: =1/(1+$D$20)^F13 -> 0.84916433 | G14: =1/(1+$D$20)^G13 -> 0.76147018 | H14: =1/(1+$D$20)^H13 -> 0.68283231 | I14: =1/(1+$D$20)^I13 -> 0.61231546
B16: PV of FCFF | E16: =E12*E14 -> -756.03504 | F16: =F12*F14 -> 635.29322 | G16: =G12*G14 -> 2088.9688 | H16: =H12*H14 -> 3607.0788 | I16: =I12*I14 -> 5187.4491
B18: Expected Growth | D18: 0.14
B19: Terminal Value | D19: 0.045
B20: WACC | D20: ='[1]DCF (WACC)'!J44 -> 0.11516425
B22: Calculation of Terminal Value
B24: FCF (n+1) | C24: =I12*(1+D18) -> 9657.9173
B25: WACC | C25: =D20 -> 0.11516425
B26: Terminal Growth Rate | C26: =D19 -> 0.045
B28: Terminal Value | C28: =C24/(C25-C26) -> 137647.26
B30: Calculation of Enterprise Value
B32: PV of FCFF | C32: =SUM(E16:I16) -> 10762.755
B33: PV of Terminal Value | C33: =C28*I14 -> 84283.545
B34: Value of Operating Asset | C34: =SUM(C32:C33) -> 95046.3
B36: Add : cash | C36: ='Data Sheet'!K69 -> 20614.84
B37: Less : Debt | C37: ='[1]M&M PROJECT 3 Statement'!H55 -> 129024.58
B38: Value of Equity | C38: =C34+C36-C37 -> -13363.44
B39: No. of Shares | C39: ='Data Sheet'!B6 -> 124.35288
B40: Value per Share | C40: =C38/C39 -> -107.46385

Sheet Raw Data (Source)
E53: 41699 | F53: 42064 | G53: 42430 | H53: 42795 | I53: 43160 | J53: 43525 | K53: 43891 | L53: 44256 | M53: 44621 | N53: 44986 | O53: 45352 | P53: 45717
D54: Cash from Operating Activity - | E54: -244 | F54: 1055 | G54: 2385 | H54: 183 | I54: 682 | J54: -4347 | K54: -1457 | L54: 17909 | M54: 9248 | N54: -7074 | O54: -5630 | P54: 3176
D55: Profit from operations | E55: 8086 | F55: 6454 | G55: 7595 | H55: 7911 | I55: 10159 | J55: 11112 | K55: 7774 | L55: 7588 | M55: 10515 | N55: 15642 | O55: 17541 | P55: 22050
D56: Receivables | E56: -2258 | F56: -575 | G56: 177 | H56: -8609 | I56: -11918 | J56: -13712 | K56: -1516 | L56: 4896 | M56: -2506 | N56: -21702 | O56: -21777 | P56: -20952
D57: Inventory | E57: -78 | F57: -62 | G57: -1113 | H57: 241 | I57: -256 | J57: -2276 | K57: 1316 | L57: 226 | M57: -2173 | N57: -5252 | O57: -1753 | P57: -1646
D58: Payables | E58: 1094 | F58: 1169 | G58: 1939 | H58: 2645 | I58: 5361 | J58: 3466 | K58: -6775 | L58: 7049 | M58: 4972 | N58: 7013 | O58: 4354 | P58: 8485
D59: Loans Advances | E59: -5814 | F59: -4229 | G59: 0 | H59: 0 | I59: 0 | J59: 0 | K59: 0 | L59: 0 | M59: 0 | N59: 0 | O59: 0 | P59: 0
D60: Other WC items | E60: 0 | F60: 0 | G60: -4241 | H60: 0 | I60: 0 | J60: 0 | K60: 0 | L60: 0 | M60: 0 | N60: 0 | O60: 0 | P60: 0
D61: Working capital changes | E61: -7055 | F61: -3698 | G61: -3238 | H61: -5724 | I61: -6813 | J61: -12522 | K61: -6974 | L61: 12171 | M61: 293 | N61: -19941 | O61: -19175 | P61: -14113
D62: Direct taxes | E62: -1275 | F62: -1701 | G62: -1973 | H62: -2005 | I62: -2664 | J62: -2937 | K62: -2257 | L62: -1850 | M62: -1560 | N62: -2775 | O62: -3996 | P62: -4761
D63: Cash from Investing Activity - | E63: -4524 | F63: -4357 | G63: -5506 | H63: -5875 | I63: -5467 | J63: -7174 | K63: -6870 | L63: -19686 | M63: -3252 | N63: -8866 | O63: -5615 | P63: -18616
D64: Fixed assets purchased | E64: -3665 | F64: -4759 | G64: -4172 | H64: -5026 | I64: -5906 | J64: -7340 | K64: -6896 | L64: -5989 | M64: -6040 | N64: -6305 | O64: -9946 | P64: -10392
D65: Fixed assets sold | E65: 58 | F65: 43 | G65: 59 | H65: 63 | I65: 115 | J65: 142 | K65: 102 | L65: 1364 | M65: 120 | N65: 138 | O65: 273 | P65: 583
... D92: Reserves | E92: 23012 | F92: 25561 | G92: 26222 | H92: 29467 | I92: 36232 | J92: 39439 | K92: 39415 | L92: 41027 | M92: 46567 | N92: 55809 | O92: 65633 | P92: 76481
D93: Borrowings - | E93: 35167 | F93: 37911 | G93: 41553 | H93: 48762 | I93: 55898 | J93: 70848
D94: Long term Borrowings | E94: 25492 | F94: 22327 | G94: 23599 | H94: 30125 | I94: 33809 | J94: 43526 | K94: 52298 | L94: 52778 | M94: 48625 | N94: 55027 | O94: 69741 | P94: 83782
D95: Short term Borrowings | E95: 2781 | F95: 7177 | G95: 7077 | H95: 10122 | I95: 11326 | J95: 10541 | K95: 10218 | L95: 4647 | M95: 26042 | N95: 33740 | O95: 35484 | P95: 41466
D96: Lease Liabilities | E96: 0 | F96: 0 | G96: 0 | H96: 0 | I96: 0 | J96: 0 | K96: 0 | L96: 2666 | M96: 2938 | N96: 3480 | O96: 3422 | P96: 3776
D97: Preference Capital | E97: 0 | F97: 0 | G97: 0 | H97: 0 | I97: 0 | J97: 0 | K97: 0 | L97: 0 | M97: 0 | N97: 0 | O97: 2022 | P97: 4075
D98: Other Borrowings | E98: 6894 | F98: 8407 | G98: 10877 | H98: 8516 | I98: 10763 | J98: 16781 | K98: 19577 | L98: 20533 | M98: 0 | N98: 0 | O98: -2022 | P98: -4075
D99: Other Liabilities - | E99: 29415 | F99: 30608 | G99: 31806 | H99: 35296 | I99: 43696 | J99: 51057
D100: Non controlling int | E100: 5733 | F100: 5892 | G100: 5920 | H100: 6357 | I100: 8250 | J100: 8361 | K100: 7692 | L100: 9070 | M100: 9703 | N100: 10716 | O100: 11319 | P100: 12059
D101: Trade Payables | E101: 11800 | F101: 11421 | G101: 13376 | H101: 14797 | I101: 18287 | J101: 20992 | K101: 14985 | L101: 15506 | M101: 19037 | N101: 23836 | O101: 25666 | P101: 30855
D102: Advance from Customers | E102: 0 | F102: 0 | G102: 801 | H102: 515 | I102: 844 | J102: 0 | K102: 0 | L102: 0 | M102: 0 | N102: 0 | O102: 0 | P102: 0
D103: Other liability items | E103: 11882 | F103: 13295 | G103: 11709 | H103: 13627 | I103: 16314 | J103: 21704 | K103: 20977 | L103: 18185 | M103: 18921 | N103: 21119 | O103: 22900 | P103: 27035
D104: Total Liabilities | E104: 87889 | F104: 94376 | G104: 99852 | H104: 113835 | I104: 136369 | J104: 161889 | K104: 165716 | L104: 164968 | M104: 172388 | N104: 204283 | O104: 234722 | P104: 276013
D106: Fixed Assets - | E106: 18381 | F106: 19047 | G106: 20585 | H106: 20989 | I106: 26182 | J106: 28983
D107: Land | E107: 3421 | F107: 3693 | G107: 3575 | H107: 4027 | I107: 4285 | J107: 4295 | K107: 4511 | L107: 1712 | M107: 1931 | N107: 1977 | O107: 2098 | P107: 2115
D108: Building | E108: 7192 | F108: 7666 | G108: 7958 | H108: 8084 | I108: 8842 | J108: 9037 | K108: 11956 | L108: 8482 | M108: 9728 | N108: 10862 | O108: 11496 | P108: 13100
D109: Plant Machinery | E109: 23026 | F109: 25285 | G109: 27333 | H109: 28316 | I109: 32713 | J109: 35762 | K109: 38492 | L109: 22386 | M109: 26484 | N109: 24928 | O109: 27230 | P109: 32547
D110: Equipments | E110: 229 | F110: 268 | G110: 317 | H110: 351 | I110: 372 | J110: 384 | K110: 417 | L110: 418 | M110: 445 | N110: 452 | O110: 481 | P110: 493
D111: Furniture n fittings | E111: 1109 | F111: 909 | G111: 944 | H111: 974 | I111: 1059 | J111: 1079 | K111: 1160 | L111: 805 | M111: 844 | N111: 925 | O111: 1011 | P111: 1118
D112: Vehicles | E112: 573 | F112: 615 | G112: 652 | H112: 703 | I112: 788 | J112: 847 | K112: 1068 | L112: 986 | M112: 1090 | N112: 1238 | O112: 1356 | P112: 1593
D113: Intangible Assets | E113: 2835 | F113: 890 | G113: 3298 | H113: 3915 | I113: 7216 | J113: 9696 | K113: 9733 | L113: 6932 | M113: 7046 | N113: 10625 | O113: 11589 | P113: 13723
D114: Other fixed assets | E114: 622 | F114: 2236 | G114: 646 | H114: 758 | I114: 1064 | J114: 1113 | K114: 1265 | L114: 937 | M114: 958 | N114: 1084 | O114: 1202 | P114: 1454
D115: Gross Block | E115: 39008 | F115: 41563 | G115: 44723 | H115: 47128 | I115: 56339 | J115: 62211 | K115: 68602 | L115: 42658 | M115: 48526 | N115: 52090 | O115: 56462 | P115: 66143
D116: Accumulated Depreciation | E116: 20627 | F116: 22516 | G116: 24138 | H116: 26139 | I116: 30157 | J116: 33229 | K116: 38913 | L116: 21278 | M116: 22508 | N116: 24950 | O116: 28333 | P116: 31506
D117: Net Block | K117: =K115-K116 -> 29689 | L117: =L115-L116 -> 21380 | M117: =M115-M116 -> 26018 | N117: =N115-N116 -> 27140 | O117: =O115-O116 -> 28129 | P117: =P115-P116 -> 34637
D119: CWIP | E119: 2191 | F119: 3032 | G119: 2371 | H119: 4279 | I119: 4269 | J119: 4760 | K119: 6856 | L119: 7873 | M119: 6703 | N119: 3969 | O119: 8039 | P119: 8298
D120: Investments | E120: 8082 | F120: 10027 | G120: 11603 | H120: 14662 | I120: 16018 | J120: 18268 | K120: 19210 | L120: 28778 | M120: 30060 | N120: 35272 | O120: 35208 | P120: 41309
...

Sheet Data Sheet
A1: COMPANY NAME | B1: MAHINDRA & MAHINDRA LTD | E1: =IF(B2<>B3, "A NEW VERSION OF THE WORKSHEET IS AVAILABLE", "")
A2: LATEST VERSION | B2: 2.1 | E2: PLEASE DO NOT MAKE ANY CHANGES TO THIS SHEET
A3: CURRENT VERSION | B3: 2.1
A5: META
A6: Number of shares | B6: =IF(B9>0, B9/B8, 0) -> 124.35288
A7: Face Value | B7: 5
A8: Current Price | B8: 2970
A9: Market Capitalization | B9: 369328.06
A15: PROFIT & LOSS | B15: =B26+B34 -> 13516.85 | K15: =K17-K18-K20-K21-K22-K23-K19 -> 36511.54
A16: Report Date | B16: 42460 | C16: 42825 | D16: 43190 | E16: 43555 | F16: 43921 | G16: 44286 | H16: 44651 | I16: 45016 | J16: 45382 | K16: 45747
A17: Sales | B17: 75841.42 | C17: 83773.05 | D17: 92093.95 | E17: 104720.68 | F17: 75381.93 | G17: 74277.78 | H17: 90170.57 | I17: 121268.55 | J17: 139078.27 | K17: 159210.82
A18: Raw Material Cost | B18: 45584.35 | C18: 50655.2 | D18: 53457.29 | E18: 61881.19 | F18: 37595.3 | G18: 38271.2 | H18: 52664.85 | I18: 76019.87 | J18: 85070.07 | K18: 95754.9
A19: Change in Inventory | B19: 458.51 | C19: 13.83 | D19: -83.33 | E19: 1730.48 | F19: -826.62 | G19: -135.59 | H19: 861.66 | I19: 2032.31 | J19: 1455.32 | K19: 12.18
A20: Power and Fuel | B20: 639.97 | C20: 657.06 | D20: 733.9 | E20: 817.11 | F20: 530.92 | G20: 429.56 | H20: 541.27 | I20: 830.48 | J20: 752.73 | K20: 832.35
A21: Other Mfr. Exp | B21: 2618.7 | C21: 3255.3 | D21: 3590.26 | E21: 4253 | F21: 3277.79 | G21: 2523.4 | H21: 3124.27 | I21: 3838.42 | J21: 3791.75 | K21: 4162.28
A22: Employee Cost | B22: 7689.4 | C22: 8910.63 | D22: 10004.62 | E22: 11242.08 | F22: 8214.82 | G22: 7813.26 | H22: 8386.74 | I22: 9677.95 | J22: 10624.33 | K22: 11126.17
A23: Selling and admin | B23: 5758.86 | C23: 6253.64 | D23: 7591.15 | E23: 9658.98 | F23: 6316.52 | G23: 4628.75 | H23: 5977.67 | I23: 7681.87 | J23: 9832.2 | K23: 10811.4
A24: Other Expenses | B24: 3926.21 | C24: 3320.22 | D24: 3407.3 | E24: 3392.29 | F24: 8462.21 | G24: 8989 | H24: 5654.58 | I24: 4966.98 | J24: 5570.58 | K24: 6017.71
A25: Other Income | B25: 1398.83 | C25: 2076.61 | D25: 4366.41 | E25: 2676.45 | F25: 884.69 | G25: 1151.51 | H25: 3204.47 | I25: 3961.45 | J25: 3297.85 | K25: 3718.47
A26: Depreciation | B26: 2441.65 | C26: 2812.72 | D26: 3279.9 | E26: 3990.77 | F26: 3366.68 | G26: 3378.11 | H26: 3507.5 | I26: 4356.81 | J26: 4723.78 | K26: 6073.65
A27: Interest | B27: 3367.59 | C27: 3648.46 | D27: 3987.09 | E27: 5021.35 | F27: 6021.15 | G27: 6102.22 | H27: 5018.05 | I27: 5829.7 | J27: 7488.21 | K27: 9083.39
... A31: Dividend Amount | B31: 648.96 | C31: 807.43 | D31: 814.7 | E31: 924.73 | F31: 260.51 | G31: 971.51 | H31: 1284.5 | I31: 1809.66 | J31: 2352.14 | K31: 2824.24
A32: Effective Tax Rate | B32: =B29/B28 -> 0.37332842 | C32: =C29/C28 -> 0.36214738 | D32: =D29/D28 -> 0.22930855 | E32: =E29/E28 -> 0.32172714 | F32: =F29/F28 -> 1.1940034 | G32: =G29/G28 -> 0.52112279 | H32: =H29/H28 -> 0.22525228 | I32: =I29/I28 -> 0.1910175 | ... K32: =K29/K28 -> 0.26239778
A34: EBITDA | B34: =+B30+B29+B27+B26 -> 11075.2 | C34: =+C30+C29+C27+C26 -> 12458.95 | D34: =+D30+D29+D27+D26 -> 17145.11 | E34: =+E30+E29+E27+E26 -> 17181.57 | F34: =+F30+F29+F27+F26 -> 11490.48 | G34: =+G30+G29+G27+G26 -> 12938.63 | H34: =+H30+H29+H27+H26 -> 17211.63 | I34: =+I30+I29+I27+I26 -> 23153.76 | ... K34: =+K30+K29+K27+K26 -> 33092.59
A40: Quarters
A41: Report Date | B41: 45199 | C41: 45291 | D41: 45382 | E41: 45473 | F41: 45565 | G41: 45657 | H41: 45747 | I41: 45838 | J41: 45930 | K41: 46022
A42: Sales | B42: 34435.52 | C42: 35299.39 | D42: 35451.73 | E42: 37217.72 | F42: 37923.74 | G42: 41470.05 | H42: 42599.31 | I42: 45529.19 | J42: 46105.67 | K42: 52099.75
A43: Expenses | B43: 28705.94 | C43: 29075.41 | D43: 28847.82 | E43: 29974.6 | F43: 30790.34 | G43: 33239.32 | H43: 34688.37 | I43: 37301.39 | J43: 37165.76 | K43: 41939.37
A44: Other Income | B44: 811.95 | C44: 755.69 | D44: 750.44 | E44: 733.21 | F44: 1125.57 | G44: 718.59 | H44: 1141.1 | I44: 1395.06 | J44: 1133.94 | K44: 976.43
A45: Depreciation | B45: 1138.64 | C45: 1122.59 | D45: 1335.05 | E45: 1247.77 | F45: 1301.99 | G45: 1495.17 | H45: 2028.72 | I45: 1547.56 | J45: 1668.89 | K45: 2162.89
A46: Interest | B46: 1835.19 | C46: 1944.88 | D46: 1989.3 | E46: 2107.69 | F46: 2217.02 | G46: 2362.16 | H46: 2396.52 | I46: 2431.19 | J46: 2347.03 | K46: 2405.3
A47: Profit before tax | B47: 3567.7 | C47: 3912.2 | D47: 4030 | E47: 4620.87 | F47: 4739.96 | G47: 5091.99 | H47: 4626.8 | I47: 5644.11 | J47: 6057.93 | K47: 6568.62
A48: Tax | B48: 1083.73 | C48: 935.16 | D48: 905.06 | E48: 1075.09 | F48: 1378.9 | G48: 1467.51 | H48: 1084.95 | I48: 1267.53 | J48: 2094.18 | K48: 1547.15
A49: Net profit | B49: 2347.75 | C49: 2658.4 | D49: 2754.08 | E49: 3282.63 | F49: 3170.72 | G49: 3180.58 | H49: 3295.17 | I49: 4083.32 | J49: 3673.32 | K49: 4674.64
A50: Operating Profit | B50: 5729.58 | C50: 6223.98 | D50: 6603.91 | E50: 7243.12 | F50: 7133.4 | G50: 8230.73 | H50: 7910.94 | I50: 8227.8 | J50: 8939.91 | K50: 10160.38
A51: EBITDA | B51: =B49+B48+B46+B45 -> 6405.31 | C51: =C49+C48+C46+C45 -> 6661.03 | D51: =D49+D48+D46+D45 -> 6983.49 | E51: =E49+E48+E46+E45 -> 7713.18 | F51: =F49+F48+F46+F45 -> 8068.63 | G51: =G49+G48+G46+G45 -> 8505.42 | H51: =H49+H48+H46+H45 -> 8805.36 | I51: =I49+I48+I46+I45 -> 9329.6 | ... K51: =K49+K48+K46+K45 -> 10789.98
A55: BALANCE SHEET
A56: Report Date | B56: 42460 | C56: 42825 | D56: 43190 | E56: 43555 | F56: 43921 | G56: 44286 | H56: 44651 | I56: 45016 | J56: 45382 | K56: 45747
A57: Equity Share Capital | B57: 270.4 | C57: 310.55 | D57: 543.13 | E57: 543.96 | F57: 554.28 | G57: 555.15 | H57: 556.06 | I57: 556.82 | J57: 557.38 | K57: 558.15
A58: Reserves | B58: 26222.25 | C58: 29467.1 | D58: 36232.06 | E58: 39439.45 | F58: 39415.03 | G58: 41026.77 | H58: 46566.58 | I58: 55808.97 | J58: 65633.17 | K58: 76480.71
...
